Workbook
Name c_category: Clean!$D$2:$D$2001
Name c_contributor: Clean!$H$2:$H$2001
Name c_currency: Clean!$F$2:$F$2001
Name c_month: Clean!$J$2:$J$2001
Name c_name_flag: Clean!$M$2:$M$2001
Name c_store: Clean!$G$2:$G$2001
Name c_usd: Clean!$L$2:$L$2001

Sheet README
A1: Global Retail Price Analysis (Excel)
A3: Purpose | B3: Clean, model and report on 2,000 crowdsourced retail price observations from the Open Prices dataset (Open Food Facts).
A4: Source file | B4: global_retail_prices_dataset.csv (2,000 rows, 12 columns, recorded 7 Feb 2026 to 3 Oct 2026).
A5: Base currency | B5: All converted prices are in US dollars (USD), which is the common reference currency for comparison.
A6: Licence | B6: ODbL. Cite Open Food Facts and the Open Prices contributors if you reuse this.
A8: Sheet guide
A9: Dashboard | B9: KPIs with a currency selector (yellow cell, default All), plus monthly and currency charts.
A10: Analysis | B10: Formula-driven summaries by currency, store and month. COUNTIFS and AVERAGEIFS only, no pivots.
A11: Clean | B11: Cleaned Excel Table (tblPrices) with helper formula columns for the USD conversion. store and contributor are remapped from the mislabelled source columns (Cleaning_Log #7, #8).
A12: Raw | B12: Untouched copy of the source CSV. Do not edit.
A13: Cleaning_Log | B13: Each data quality issue, how many rows it affects (live formulas), and the action taken.
A14: Assumptions | B14: Exchange rates to USD. These are illustrative placeholders. Update them before drawing conclusions.
A16: Key caveat | B16: Prices are recorded in local currency. Converted USD values depend on the exchange rates, and the rates here are approximations.

Sheet Dashboard
A1: Retail Price Dashboard (USD)
A3: Select currency: | B3: All
A5: Records | C5: Average price (USD) | E5: Min price (USD)
A6: =IF($B$3="All",COUNTA(c_currency),COUNTIFS(c_currency,$B$3)) -> 2000 | C6: =IF($B$3="All",AVERAGE(c_usd),AVERAGEIFS(c_usd,c_currency,$B$3)) -> 4.8155912 | E6: =IF($B$3="All",MIN(c_usd),_xlfn.MINIFS(c_usd,c_currency,$B$3)) -> 0.16763006
A8: Max price (USD) | C8: Unnamed products | E8: Uncategorised rows
A9: =IF($B$3="All",MAX(c_usd),_xlfn.MAXIFS(c_usd,c_currency,$B$3)) -> 43.99 | C9: =IF($B$3="All",COUNTIF(c_name_flag,"Yes"),COUNTIFS(c_name_flag,"Yes",c_currency,$B$3)) -> 461 | E9: =IF($B$3="All",COUNTIF(c_category,"Uncategorised"),COUNTIFS(c_category,"Uncategorised",c_currency,$B$3)) -> 1866
A13: Prices converted to USD using the illustrative rates on the Assumptions sheet.

Sheet Raw
A1: price_record_id | B1: product_code | C1: product_name | D1: brand | E1: category | F1: price | G1: currency | H1: price_is_discounted | I1: store_name | J1: city | K1: country_code | L1: date_recorded
A2: 339639 | C2: APFEL ROT LOSE | E2: en:apples | F2: 2.08 | G2: EUR | H2: False | I2: jbieber | J2: Hofer | L2: 2026-10-03
A3: 339638 | B3: 4061461467661 | C3: Orient. Salat 200g | F3: 1.29 | G3: EUR | H3: False | I3: jbieber | J3: Hofer | L3: 2026-10-03
A4: 339637 | C4: Toskanabrot 360g | E4: en:white-breads | F4: 1.8 | G4: EUR | H4: False | I4: jbieber | J4: Hofer | L4: 2026-10-03
A5: 339636 | B5: 4061464512245 | C5: Waffelhörn. Erdb. | F5: 0.49 | G5: EUR | H5: False | I5: jbieber | J5: Hofer | L5: 2026-10-03
A6: 339635 | B6: 4061458026819 | C6: Orient. Salat 200g | F6: 1.29 | G6: EUR | H6: False | I6: jbieber | J6: Hofer | L6: 2026-10-03
A7: 339634 | B7: 4061461866518 | F7: 0.49 | G7: EUR | H7: False | I7: jbieber | J7: Hofer | L7: 2026-10-03
A8: 339633 | B8: 4061464955394 | C8: Milchbrötchen | F8: 1.85 | G8: EUR | H8: False | I8: jbieber | J8: Hofer | L8: 2026-10-03
A9: 339632 | B9: 4061458024068 | C9: Hummus 200 g | F9: 1.69 | G9: EUR | H9: False | I9: jbieber | J9: Hofer | L9: 2026-10-03
A10: 339630 | B10: 4099200057439 | C10: Schokolade 100g | F10: 0.89 | G10: EUR | H10: False | I10: jbieber | J10: Hofer | L10: 2026-10-03
A11: 339631 | B11: 4099200057378 | C11: Noisette 100g | F11: 1.25 | G11: EUR | H11: False | I11: jbieber | J11: Hofer | L11: 2026-10-03
A12: 339629 | C12: Bananen lose | E12: en:bananas | F12: 1.59 | G12: EUR | H12: False | I12: jbieber | J12: Hofer | L12: 2026-10-03
A13: 339628 | B13: 4061462695674 | C13: Fruchtjoghurt 180g | F13: 0.52 | G13: EUR | H13: False | I13: jbieber | J13: Hofer | L13: 2026-10-03
A14: 339627 | B14: 4099200029283 | C14: Fruchtjoghurt 180g | F14: 0.52 | G14: EUR | H14: False | I14: jbieber | J14: Hofer | L14: 2026-10-03
A15: 339626 | B15: 4099200047164 | C15: Gourmet Chips 125g | F15: 1.79 | G15: EUR | H15: False | I15: jbieber | J15: Hofer | L15: 2026-10-03
A16: 339625 | B16: 4061461374655 | C16: Apfelmus 710g | F16: 1.59 | G16: EUR | H16: False | I16: jbieber | J16: Hofer | L16: 2026-10-03
A17: 339624 | B17: 4061461035891 | C17: Instant Nudeln 255 | F17: 1.45 | G17: EUR | H17: False | I17: jbieber | J17: Hofer | L17: 2026-10-03
A18: 339623 | C18: Schoko Donut 55g | E18: en:doughnuts | F18: 0.39 | G18: EUR | H18: False | I18: jbieber | J18: Hofer | L18: 2026-10-03
A19: 339621 | B19: 4061459176377 | C19: Gouda Sch. 250/200g | F19: 1.99 | G19: EUR | H19: False | I19: jbieber | J19: Hofer | L19: 2026-10-03
A20: 339622 | C20: Kaisersemmel | E20: en:bread-rolls | F20: 0.23 | G20: EUR | H20: False | I20: jbieber | J20: Hofer | L20: 2026-10-03
A21: 339620 | B21: 7394376623769 | F21: 28.29 | G21: SEK | H21: False | I21: freso | J21: Willys Landskrona Infarten | L21: 2026-09-06
A22: 339619 | B22: 7394376624094 | F22: 28.29 | G22: SEK | H22: False | I22: freso | J22: Willys Landskrona Infarten | L22: 2026-09-06
A23: 339618 | B23: 5411188119753 | F23: 22.9 | G23: SEK | H23: False | I23: freso | J23: Willys Landskrona Infarten | L23: 2026-09-06
A24: 339617 | B24: 3564707087957 | C24: BIO VILL FLAN NAPPE 4X125G | F24: 1.71 | G24: EUR | H24: False | I24: poslovitch | J24: E. Leclerc | L24: 2026-10-03
A25: 339616 | B25: 3273220083260 | C25: SOJASUN MYRTILLES 4 x 100g | F25: 1.69 | G25: EUR | H25: False | I25: poslovitch | J25: E. Leclerc | L25: 2026-10-03
A26: 339615 | B26: 8715700421841 | C26: HEINZ SCE AMERICAN BURG 230G | F26: 1.73 | G26: EUR | H26: False | I26: poslovitch | J26: E. Leclerc | L26: 2026-10-03
A27: 339614 | B27: 3599741001898 | C27: FIND FLT CABILLAUD 4X100G FINDUS 400g | F27: 10.19 | G27: EUR | H27: False | I27: poslovitch | J27: E. Leclerc | L27: 2026-10-03
A28: 339613 | B28: 3564700407646 | C28: P OCEAN PAVES SAUMON 2 x 125g | F28: 4.99 | G28: EUR | H28: False | I28: poslovitch | J28: E. Leclerc | L28: 2026-10-03
A29: 339612 | B29: 8710522921500 | C29: MAYO 5 ING SPL AMORA 235G | F29: 2.43 | G29: EUR | H29: False | I29: poslovitch | J29: E. Leclerc | L29: 2026-10-03
A30: 339611 | B30: 3228857000371 | C30: HARRYS BURGER NATURE 300G | F30: 1.55 | G30: EUR | H30: False | I30: poslovitch | J30: E. Leclerc | L30: 2026-10-03
A31: 339610 | B31: 3394230110613 | C31: SOIGNON BOITE LE CHEVRE 180G | F31: 2.91 | G31: EUR | H31: False | I31: poslovitch | J31: E. Leclerc | L31: 2026-10-03
A32: 339609 | B32: 3023260022459 | C32: ISTARA P'TIT BASQUE CLOC 220G | F32: 5.39 | G32: EUR | H32: False | I32: poslovitch | J32: E. Leclerc | L32: 2026-10-03
A33: 339608 | B33: 7613035694897 | C33: HERTA LBV PAVE EPIN FR 180G GARDEN GOURMET | F33: 2.38 | G33: EUR | H33: False | I33: poslovitch | J33: E. Leclerc | L33: 2026-10-03
A34: 339607 | B34: 3770016162098 | C34: CHIPOLATAS VEGE/GOURMANDES 200G HAPPYVORE | F34: 3.71 | G34: EUR | H34: False | I34: poslovitch | J34: E. Leclerc | L34: 2026-10-03
A35: 339606 | B35: 3600900005067 | C35: TIPIAK MELI MELO GOURM 330G | F35: 2.24 | G35: EUR | H35: False | I35: poslovitch | J35: E. Leclerc | L35: 2026-10-03
... A129: 339512 | B129: 3272770097178 | C129: TARTARE NOIX & AMANDES 150G | F129: 1.95 | G129: EUR | H129: False | I129: poslovitch | J129: E. Leclerc | L129: 2026-10-03
A130: 339511 | B130: 7340083453106 | F130: 16.94 | G130: SEK | H130: False | I130: freso | J130: Willys Landskrona Infarten | L130: 2026-09-06
A131: 339510 | B131: 3155250345177 | C131: RONDEL.RAIS.FIG/NX 30.5%MG 125G | F131: 1.83 | G131: EUR | H131: False | I131: poslovitch | J131: E. Leclerc | L131: 2026-10-03
A132: 339509 | B132: 3273220012123 | C132: TRIBALLAT, PETIT BILLY,200G | F132: 2.78 | G132: EUR | H132: False | I132: poslovitch | J132: E. Leclerc | L132: 2026-10-03
A133: 339508 | B133: 3394230003144 | C133: SOIGNON BUCHETTE 120G | F133: 2.01 | G133: EUR | H133: False | I133: poslovitch | J133: E. Leclerc | L133: 2026-10-03
...

Sheet Assumptions
A1: Exchange rates to USD (illustrative placeholders, update before use)
A2: Rate = USD per 1 unit of the currency. Yellow cells are inputs.
A3: Currency | B3: USD per 1 unit
A4: BAM | B4: 0.57803468
A5: BIF | B5: 0.00033898305
A6: BRL | B6: 0.18181818
A7: CLP | B7: 0.0010638298
A8: CZK | B8: 0.044444444
A9: EUR | B9: 1.0869565
A10: GBP | B10: 1.2658228
A11: HUF | B11: 0.0028169014
A12: ILS | B12: 0.27027027
A13: INR | B13: 0.011904762
A14: KZT | B14: 0.0020833333
A15: MAD | B15: 0.10204082
... A23: USD | B23: 1

Sheet Clean
A1: price_record_id | B1: product_code | C1: product_name | D1: category | E1: price_local | F1: currency | G1: store | H1: contributor | I1: date_recorded | J1: month | K1: fx_to_usd | L1: price_usd | M1: flag_unnamed_product
A2: 339639 | C2: APFEL ROT LOSE | D2: en:apples | E2: 2.08 | F2: EUR | G2: Hofer | H2: jbieber | I2: 46298 | J2: 46296 | K2: =INDEX(Assumptions!$B$4:$B$23,MATCH(F2,Assumptions!$A$4:$A$23,0)) -> 1.0869565 | L2: =E2*K2 -> 2.2608696 | M2: =IF(C2="Unnamed product","Yes","No") -> No
A3: 339638 | B3: 4061461467661 | C3: Orient. Salat 200g | D3: Uncategorised | E3: 1.29 | F3: EUR | G3: Hofer | H3: jbieber | I3: 46298 | J3: 46296 | K3: =INDEX(Assumptions!$B$4:$B$23,MATCH(F3,Assumptions!$A$4:$A$23,0)) -> 1.0869565 | L3: =E3*K3 -> 1.4021739 | M3: =IF(C3="Unnamed product","Yes","No") -> No
A4: 339637 | C4: Toskanabrot 360g | D4: en:white-breads | E4: 1.8 | F4: EUR | G4: Hofer | H4: jbieber | I4: 46298 | J4: 46296 | K4: =INDEX(Assumptions!$B$4:$B$23,MATCH(F4,Assumptions!$A$4:$A$23,0)) -> 1.0869565 | L4: =E4*K4 -> 1.9565217 | M4: =IF(C4="Unnamed product","Yes","No") -> No
A5: 339636 | B5: 4061464512245 | C5: Waffelhörn. Erdb. | D5: Uncategorised | E5: 0.49 | F5: EUR | G5: Hofer | H5: jbieber | I5: 46298 | J5: 46296 | K5: =INDEX(Assumptions!$B$4:$B$23,MATCH(F5,Assumptions!$A$4:$A$23,0)) -> 1.0869565 | L5: =E5*K5 -> 0.5326087 | M5: =IF(C5="Unnamed product","Yes","No") -> No
A6: 339635 | B6: 4061458026819 | C6: Orient. Salat 200g | D6: Uncategorised | E6: 1.29 | F6: EUR | G6: Hofer | H6: jbieber | I6: 46298 | J6: 46296 | K6: =INDEX(Assumptions!$B$4:$B$23,MATCH(F6,Assumptions!$A$4:$A$23,0)) -> 1.0869565 | L6: =E6*K6 -> 1.4021739 | M6: =IF(C6="Unnamed product","Yes","No") -> No
A7: 339634 | B7: 4061461866518 | C7: Unnamed product | D7: Uncategorised | E7: 0.49 | F7: EUR | G7: Hofer | H7: jbieber | I7: 46298 | J7: 46296 | K7: =INDEX(Assumptions!$B$4:$B$23,MATCH(F7,Assumptions!$A$4:$A$23,0)) -> 1.0869565 | L7: =E7*K7 -> 0.5326087 | M7: =IF(C7="Unnamed product","Yes","No") -> Yes
A8: 339633 | B8: 4061464955394 | C8: Milchbrötchen | D8: Uncategorised | E8: 1.85 | F8: EUR | G8: Hofer | H8: jbieber | I8: 46298 | J8: 46296 | K8: =INDEX(Assumptions!$B$4:$B$23,MATCH(F8,Assumptions!$A$4:$A$23,0)) -> 1.0869565 | L8: =E8*K8 -> 2.0108696 | M8: =IF(C8="Unnamed product","Yes","No") -> No
A9: 339632 | B9: 4061458024068 | C9: Hummus 200 g | D9: Uncategorised | E9: 1.69 | F9: EUR | G9: Hofer | H9: jbieber | I9: 46298 | J9: 46296 | K9: =INDEX(Assumptions!$B$4:$B$23,MATCH(F9,Assumptions!$A$4:$A$23,0)) -> 1.0869565 | L9: =E9*K9 -> 1.8369565 | M9: =IF(C9="Unnamed product","Yes","No") -> No
A10: 339630 | B10: 4099200057439 | C10: Schokolade 100g | D10: Uncategorised | E10: 0.89 | F10: EUR | G10: Hofer | H10: jbieber | I10: 46298 | J10: 46296 | K10: =INDEX(Assumptions!$B$4:$B$23,MATCH(F10,Assumptions!$A$4:$A$23,0)) -> 1.0869565 | L10: =E10*K10 -> 0.9673913 | M10: =IF(C10="Unnamed product","Yes","No") -> No
A11: 339631 | B11: 4099200057378 | C11: Noisette 100g | D11: Uncategorised | E11: 1.25 | F11: EUR | G11: Hofer | H11: jbieber | I11: 46298 | J11: 46296 | K11: =INDEX(Assumptions!$B$4:$B$23,MATCH(F11,Assumptions!$A$4:$A$23,0)) -> 1.0869565 | L11: =E11*K11 -> 1.3586957 | M11: =IF(C11="Unnamed product","Yes","No") -> No
A12: 339629 | C12: Bananen lose | D12: en:bananas | E12: 1.59 | F12: EUR | G12: Hofer | H12: jbieber | I12: 46298 | J12: 46296 | K12: =INDEX(Assumptions!$B$4:$B$23,MATCH(F12,Assumptions!$A$4:$A$23,0)) -> 1.0869565 | L12: =E12*K12 -> 1.7282609 | M12: =IF(C12="Unnamed product","Yes","No") -> No
A13: 339628 | B13: 4061462695674 | C13: Fruchtjoghurt 180g | D13: Uncategorised | E13: 0.52 | F13: EUR | G13: Hofer | H13: jbieber | I13: 46298 | J13: 46296 | K13: =INDEX(Assumptions!$B$4:$B$23,MATCH(F13,Assumptions!$A$4:$A$23,0)) -> 1.0869565 | L13: =E13*K13 -> 0.56521739 | M13: =IF(C13="Unnamed product","Yes","No") -> No
A14: 339627 | B14: 4099200029283 | C14: Fruchtjoghurt 180g | D14: Uncategorised | E14: 0.52 | F14: EUR | G14: Hofer | H14: jbieber | I14: 46298 | J14: 46296 | K14: =INDEX(Assumptions!$B$4:$B$23,MATCH(F14,Assumptions!$A$4:$A$23,0)) -> 1.0869565 | L14: =E14*K14 -> 0.56521739 | M14: =IF(C14="Unnamed product","Yes","No") -> No
A15: 339626 | B15: 4099200047164 | C15: Gourmet Chips 125g | D15: Uncategorised | E15: 1.79 | F15: EUR | G15: Hofer | H15: jbieber | I15: 46298 | J15: 46296 | K15: =INDEX(Assumptions!$B$4:$B$23,MATCH(F15,Assumptions!$A$4:$A$23,0)) -> 1.0869565 | L15: =E15*K15 -> 1.9456522 | M15: =IF(C15="Unnamed product","Yes","No") -> No
A16: 339625 | B16: 4061461374655 | C16: Apfelmus 710g | D16: Uncategorised | E16: 1.59 | F16: EUR | G16: Hofer | H16: jbieber | I16: 46298 | J16: 46296 | K16: =INDEX(Assumptions!$B$4:$B$23,MATCH(F16,Assumptions!$A$4:$A$23,0)) -> 1.0869565 | L16: =E16*K16 -> 1.7282609 | M16: =IF(C16="Unnamed product","Yes","No") -> No
A17: 339624 | B17: 4061461035891 | C17: Instant Nudeln 255 | D17: Uncategorised | E17: 1.45 | F17: EUR | G17: Hofer | H17: jbieber | I17: 46298 | J17: 46296 | K17: =INDEX(Assumptions!$B$4:$B$23,MATCH(F17,Assumptions!$A$4:$A$23,0)) -> 1.0869565 | L17: =E17*K17 -> 1.576087 | M17: =IF(C17="Unnamed product","Yes","No") -> No
A18: 339623 | C18: Schoko Donut 55g | D18: en:doughnuts | E18: 0.39 | F18: EUR | G18: Hofer | H18: jbieber | I18: 46298 | J18: 46296 | K18: =INDEX(Assumptions!$B$4:$B$23,MATCH(F18,Assumptions!$A$4:$A$23,0)) -> 1.0869565 | L18: =E18*K18 -> 0.42391304 | M18: =IF(C18="Unnamed product","Yes","No") -> No
A19: 339621 | B19: 4061459176377 | C19: Gouda Sch. 250/200g | D19: Uncategorised | E19: 1.99 | F19: EUR | G19: Hofer | H19: jbieber | I19: 46298 | J19: 46296 | K19: =INDEX(Assumptions!$B$4:$B$23,MATCH(F19,Assumptions!$A$4:$A$23,0)) -> 1.0869565 | L19: =E19*K19 -> 2.1630435 | M19: =IF(C19="Unnamed product","Yes","No") -> No
A20: 339622 | C20: Kaisersemmel | D20: en:bread-rolls | E20: 0.23 | F20: EUR | G20: Hofer | H20: jbieber | I20: 46298 | J20: 46296 | K20: =INDEX(Assumptions!$B$4:$B$23,MATCH(F20,Assumptions!$A$4:$A$23,0)) -> 1.0869565 | L20: =E20*K20 -> 0.25 | M20: =IF(C20="Unnamed product","Yes","No") -> No
A21: 339620 | B21: 7394376623769 | C21: Unnamed product | D21: Uncategorised | E21: 28.29 | F21: SEK | G21: Willys Landskrona Infarten | H21: freso | I21: 46271 | J21: 46266 | K21: =INDEX(Assumptions!$B$4:$B$23,MATCH(F21,Assumptions!$A$4:$A$23,0)) -> 0.10526316 | L21: =E21*K21 -> 2.9778947 | M21: =IF(C21="Unnamed product","Yes","No") -> Yes
A22: 339619 | B22: 7394376624094 | C22: Unnamed product | D22: Uncategorised | E22: 28.29 | F22: SEK | G22: Willys Landskrona Infarten | H22: freso | I22: 46271 | J22: 46266 | K22: =INDEX(Assumptions!$B$4:$B$23,MATCH(F22,Assumptions!$A$4:$A$23,0)) -> 0.10526316 | L22: =E22*K22 -> 2.9778947 | M22: =IF(C22="Unnamed product","Yes","No") -> Yes
A23: 339618 | B23: 5411188119753 | C23: Unnamed product | D23: Uncategorised | E23: 22.9 | F23: SEK | G23: Willys Landskrona Infarten | H23: freso | I23: 46271 | J23: 46266 | K23: =INDEX(Assumptions!$B$4:$B$23,MATCH(F23,Assumptions!$A$4:$A$23,0)) -> 0.10526316 | L23: =E23*K23 -> 2.4105263 | M23: =IF(C23="Unnamed product","Yes","No") -> Yes
A24: 339617 | B24: 3564707087957 | C24: BIO VILL FLAN NAPPE 4X125G | D24: Uncategorised | E24: 1.71 | F24: EUR | G24: E. Leclerc | H24: poslovitch | I24: 46298 | J24: 46296 | K24: =INDEX(Assumptions!$B$4:$B$23,MATCH(F24,Assumptions!$A$4:$A$23,0)) -> 1.0869565 | L24: =E24*K24 -> 1.8586957 | M24: =IF(C24="Unnamed product","Yes","No") -> No
A25: 339616 | B25: 3273220083260 | C25: SOJASUN MYRTILLES 4 x 100g | D25: Uncategorised | E25: 1.69 | F25: EUR | G25: E. Leclerc | H25: poslovitch | I25: 46298 | J25: 46296 | K25: =INDEX(Assumptions!$B$4:$B$23,MATCH(F25,Assumptions!$A$4:$A$23,0)) -> 1.0869565 | L25: =E25*K25 -> 1.8369565 | M25: =IF(C25="Unnamed product","Yes","No") -> No
A26: 339615 | B26: 8715700421841 | C26: HEINZ SCE AMERICAN BURG 230G | D26: Uncategorised | E26: 1.73 | F26: EUR | G26: E. Leclerc | H26: poslovitch | I26: 46298 | J26: 46296 | K26: =INDEX(Assumptions!$B$4:$B$23,MATCH(F26,Assumptions!$A$4:$A$23,0)) -> 1.0869565 | L26: =E26*K26 -> 1.8804348 | M26: =IF(C26="Unnamed product","Yes","No") -> No
A27: 339614 | B27: 3599741001898 | C27: FIND FLT CABILLAUD 4X100G FINDUS 400g | D27: Uncategorised | E27: 10.19 | F27: EUR | G27: E. Leclerc | H27: poslovitch | I27: 46298 | J27: 46296 | K27: =INDEX(Assumptions!$B$4:$B$23,MATCH(F27,Assumptions!$A$4:$A$23,0)) -> 1.0869565 | L27: =E27*K27 -> 11.076087 | M27: =IF(C27="Unnamed product","Yes","No") -> No
A28: 339613 | B28: 3564700407646 | C28: P OCEAN PAVES SAUMON 2 x 125g | D28: Uncategorised | E28: 4.99 | F28: EUR | G28: E. Leclerc | H28: poslovitch | I28: 46298 | J28: 46296 | K28: =INDEX(Assumptions!$B$4:$B$23,MATCH(F28,Assumptions!$A$4:$A$23,0)) -> 1.0869565 | L28: =E28*K28 -> 5.423913 | M28: =IF(C28="Unnamed product","Yes","No") -> No
A29: 339612 | B29: 8710522921500 | C29: MAYO 5 ING SPL AMORA 235G | D29: Uncategorised | E29: 2.43 | F29: EUR | G29: E. Leclerc | H29: poslovitch | I29: 46298 | J29: 46296 | K29: =INDEX(Assumptions!$B$4:$B$23,MATCH(F29,Assumptions!$A$4:$A$23,0)) -> 1.0869565 | L29: =E29*K29 -> 2.6413043 | M29: =IF(C29="Unnamed product","Yes","No") -> No
A30: 339611 | B30: 3228857000371 | C30: HARRYS BURGER NATURE 300G | D30: Uncategorised | E30: 1.55 | F30: EUR | G30: E. Leclerc | H30: poslovitch | I30: 46298 | J30: 46296 | K30: =INDEX(Assumptions!$B$4:$B$23,MATCH(F30,Assumptions!$A$4:$A$23,0)) -> 1.0869565 | L30: =E30*K30 -> 1.6847826 | M30: =IF(C30="Unnamed product","Yes","No") -> No
A31: 339610 | B31: 3394230110613 | C31: SOIGNON BOITE LE CHEVRE 180G | D31: Uncategorised | E31: 2.91 | F31: EUR | G31: E. Leclerc | H31: poslovitch | I31: 46298 | J31: 46296 | K31: =INDEX(Assumptions!$B$4:$B$23,MATCH(F31,Assumptions!$A$4:$A$23,0)) -> 1.0869565 | L31: =E31*K31 -> 3.1630435 | M31: =IF(C31="Unnamed product","Yes","No") -> No
A32: 339609 | B32: 3023260022459 | C32: ISTARA P'TIT BASQUE CLOC 220G | D32: Uncategorised | E32: 5.39 | F32: EUR | G32: E. Leclerc | H32: poslovitch | I32: 46298 | J32: 46296 | K32: =INDEX(Assumptions!$B$4:$B$23,MATCH(F32,Assumptions!$A$4:$A$23,0)) -> 1.0869565 | L32: =E32*K32 -> 5.8586957 | M32: =IF(C32="Unnamed product","Yes","No") -> No
... A421: 339220 | B421: 9555750000530 | C421: HOLLAND POTATO CN 1.2KG | D421: Uncategorised | E421: 1.85 | F421: SGD | G421: Giant | H421: therealestmca | I421: 46295 | J421: 46266 | K421: =INDEX(Assumptions!$B$4:$B$23,MATCH(F421,Assumptions!$A$4:$A$23,0)) -> 0.74074074 | L421: =E421*K421 -> 1.3703704 | M421: =IF(C421="Unnamed product","Yes","No") -> No
A422: 339219 | C422: H FRESH CHICKEN BREAST | D422: en:chicken-breasts | E422: 4.92 | F422: SGD | G422: Giant | H422: therealestmca | I422: 46295 | J422: 46266 | K422: =INDEX(Assumptions!$B$4:$B$23,MATCH(F422,Assumptions!$A$4:$A$23,0)) -> 0.74074074 | L422: =E422*K422 -> 3.6444444 | M422: =IF(C422="Unnamed product","Yes","No") -> No
A423: 339218 | C423: GRASS FED MINCED BEEF | D423: en:ground-beef-meats | E423: 8.79 | F423: SGD | G423: Giant | H423: therealestmca | I423: 46295 | J423: 46266 | K423: =INDEX(Assumptions!$B$4:$B$23,MATCH(F423,Assumptions!$A$4:$A$23,0)) -> 0.74074074 | L423: =E423*K423 -> 6.5111111 | M423: =IF(C423="Unnamed product","Yes","No") -> No
A424: 339217 | C424: H FRESH CHICKEN MINCE | D424: en:ground-chicken-meat | E424: 1.6 | F424: SGD | G424: Giant | H424: therealestmca | I424: 46295 | J424: 46266 | K424: =INDEX(Assumptions!$B$4:$B$23,MATCH(F424,Assumptions!$A$4:$A$23,0)) -> 0.74074074 | L424: =E424*K424 -> 1.1851852 | M424: =IF(C424="Unnamed product","Yes","No") -> No
A425: 339216 | B425: 3302740058776 | C425: Unnamed product | D425: Uncategorised | E425: 4.51 | F425: EUR | G425: E.Leclerc Levallois | H425: g123k | I425: 46298 | J425: 46296 | K425: =INDEX(Assumptions!$B$4:$B$23,MATCH(F425,Assumptions!$A$4:$A$23,0)) -> 1.0869565 | L425: =E425*K425 -> 4.9021739 | M425: =IF(C425="Unnamed product","Yes","No") -> Yes
A426: 339215 | B426: 3023290053409 | C426: Unnamed product | D426: Uncategorised | E426: 1.69 | F426: EUR | G426: E.Leclerc Levallois | H426: g123k | I426: 46298 | J426: 46296 | K426: =INDEX(Assumptions!$B$4:$B$23,MATCH(F426,Assumptions!$A$4:$A$23,0)) -> 1.0869565 | L426: =E426*K426 -> 1.8369565 | M426: =IF(C426="Unnamed product","Yes","No") -> Yes
A427: 339214 | B427: 8885006772029 | C427: GILDA TOMATO PASTE 400G | D427: Uncategorised | E427: 2.9 | F427: SGD | G427: Fortune Supermarket | H427: therealestmca | I427: 46298 | J427: 46296 | K427: =INDEX(Assumptions!$B$4:$B$23,MATCH(F427,Assumptions!$A$4:$A$23,0)) -> 0.74074074 | L427: =E427*K427 -> 2.1481481 | M427: =IF(C427="Unnamed product","Yes","No") -> No
A428: 339213 | B428: 5949040202058 | C428: Unnamed product | D428: Uncategorised | E428: 1.05 | F428: EUR | G428: Σκλαβενίτης | H428: alexiscy | I428: 46293 | J428: 46266 | K428: =INDEX(Assumptions!$B$4:$B$23,MATCH(F428,Assumptions!$A$4:$A$23,0)) -> 1.0869565 | L428: =E428*K428 -> 1.1413043 | M428: =IF(C428="Unnamed product","Yes","No") -> Yes
...

Sheet Cleaning_Log
A1: Data quality issues and actions
A3: # | B3: Column | C3: Issue | D3: Rows affected (live) | E3: Share of rows | F3: Action taken
A4: 1 | B4: brand | C4: Column is entirely blank | D4: =COUNTBLANK(tblRaw[brand]) -> 2000 | E4: =D4/COUNTA(tblRaw[price_record_id]) -> 1 | F4: Dropped from analysis. Kept in Raw for reference.
A5: 2 | B5: country_code | C5: Column is entirely blank, although the README lists it as populated | D5: =COUNTBLANK(tblRaw[country_code]) -> 2000 | E5: =D5/COUNTA(tblRaw[price_record_id]) -> 1 | F5: Dropped. Currency used as the location proxy instead (the city column holds store names, see #8).
A6: 3 | B6: price_is_discounted | C6: Every row is FALSE, so discounts cannot be analysed | D6: =SUMPRODUCT(--(tblRaw[price_is_discounted]="False")) -> 2000 | E6: =D6/COUNTA(tblRaw[price_record_id]) -> 1 | F6: Noted. Discount analysis is not possible with this file.
A7: 4 | B7: category | C7: Mostly blank (about 93%) | D7: =COUNTBLANK(tblRaw[category]) -> 1866 | E7: =D7/COUNTA(tblRaw[price_record_id]) -> 0.933 | F7: Blanks labelled 'Uncategorised'. Category analysis limited to the labelled minority.
A8: 5 | B8: product_name | C8: Blank product names | D8: =COUNTBLANK(tblRaw[product_name]) -> 461 | E8: =D8/COUNTA(tblRaw[price_record_id]) -> 0.2305 | F8: Labelled 'Unnamed product' and flagged in Clean column M. Kept in price totals.
A9: 6 | B9: product_code | C9: Blank barcodes | D9: =COUNTBLANK(tblRaw[product_code]) -> 134 | E9: =D9/COUNTA(tblRaw[price_record_id]) -> 0.067 | F9: Left blank. Not needed for these analyses.
A10: 7 | B10: store_name | C10: Mislabelled: holds Open Food Facts contributor usernames, not stores (e.g. poslovitch, 502 rows) | D10: =COUNTA(tblRaw[store_name]) -> 2000 | E10: =D10/COUNTA(tblRaw[price_record_id]) -> 1 | F10: Source columns mislabelled: store_name holds contributor IDs, city holds store names. Remapped to the Clean 'contributor' column and excluded from store analysis.
A11: 8 | B11: city | C11: Mislabelled: holds store names, not cities (e.g. Dumbo Market, E. Leclerc). The file has no real city data | D11: =COUNTA(tblRaw[city]) -> 2000 | E11: =D11/COUNTA(tblRaw[price_record_id]) -> 1 | F11: Remapped to the Clean 'store' column. Analysis section 2 now ranks these real stores. Currency is the only location proxy.
A12: 9 | B12: currency | C12: Mixed currencies (20 codes). Local prices are not comparable | D12: =COUNTA(tblRaw[currency])-COUNTIF(tblRaw[currency],"EUR")-COUNTIF(tblRaw[currency],"USD") -> 599 | E12: =D12/COUNTA(tblRaw[price_record_id]) -> 0.2995 | F12: Converted to USD using the Assumptions sheet. Count shows rows outside EUR and USD.
A13: 10 | B13: price | C13: Very low-value currencies with large nominal numbers (BIF, KZT) | D13: =COUNTIFS(tblRaw[currency],"BIF")+COUNTIFS(tblRaw[currency],"KZT") -> 37 | E13: =D13/COUNTA(tblRaw[price_record_id]) -> 0.0185 | F13: Converted to USD. Review before trusting cross-currency averages.
A14: 11 | B14: date_recorded | C14: All dates valid, 7 Feb to 3 Oct 2026 | D14: =COUNTA(tblRaw[date_recorded]) -> 2000 | E14: =D14/COUNTA(tblRaw[price_record_id]) -> 1 | F14: No action needed. Confirmed in Analysis.
A15: 12 | B15: price_record_id | C15: No duplicate IDs or duplicate rows | D15: 0 | E15: =D15/COUNTA(tblRaw[price_record_id]) -> 0 | F15: Checked during profiling. No action needed.
A16: 13 | B16: store_name | C16: 'vanished' is a deleted contributor account, not an unknown store | D16: =COUNTIF(tblRaw[store_name],"vanished") -> 35 | E16: =D16/COUNTA(tblRaw[price_record_id]) -> 0.0175 | F16: Labelled 'Deleted account (vanished)' in the contributor column. The store on these rows (Small) is intact.
A17: 14 | B17: city | C17: Accented store names (Intermarché, Kiwi Bøhmergaten, Đurić Market) show as broken characters if the CSV is double-clicked, because Excel assumes ANSI instead of UTF-8 | D17: 192 | E17: =D17/COUNTA(tblRaw[price_record_id]) -> 0.096 | F17: Source file is valid UTF-8. Imported with UTF-8 encoding (Data > From Text/CSV, File origin 65001); every text value checked against the CSV, no corrupted characters.

Sheet Analysis
A1: Analysis (all figures are live formulas on the Clean sheet, prices in USD)
A3: 1. Records and average price by currency
A4: Currency | B4: Records | C4: Share of records | D4: Avg price (local) | E4: Avg price (USD)
A5: EUR | B5: =COUNTIFS(c_currency,A5) -> 994 | C5: =B5/COUNTA(c_currency) -> 0.497 | D5: =AVERAGEIFS(Clean!$E$2:$E$2001,c_currency,A5) -> 3.1998089 | E5: =AVERAGEIFS(c_usd,c_currency,A5) -> 3.4780531
A6: USD | B6: =COUNTIFS(c_currency,A6) -> 407 | C6: =B6/COUNTA(c_currency) -> 0.2035 | D6: =AVERAGEIFS(Clean!$E$2:$E$2001,c_currency,A6) -> 10.87774 | E6: =AVERAGEIFS(c_usd,c_currency,A6) -> 10.87774
A7: NOK | B7: =COUNTIFS(c_currency,A7) -> 190 | C7: =B7/COUNTA(c_currency) -> 0.095 | D7: =AVERAGEIFS(Clean!$E$2:$E$2001,c_currency,A7) -> 34.934368 | E7: =AVERAGEIFS(c_usd,c_currency,A7) -> 3.5287241
A8: BAM | B8: =COUNTIFS(c_currency,A8) -> 122 | C8: =B8/COUNTA(c_currency) -> 0.061 | D8: =AVERAGEIFS(Clean!$E$2:$E$2001,c_currency,A8) -> 4.3531148 | E8: =AVERAGEIFS(c_usd,c_currency,A8) -> 2.5162513
A9: SEK | B9: =COUNTIFS(c_currency,A9) -> 118 | C9: =B9/COUNTA(c_currency) -> 0.059 | D9: =AVERAGEIFS(Clean!$E$2:$E$2001,c_currency,A9) -> 23.973644 | E9: =AVERAGEIFS(c_usd,c_currency,A9) -> 2.5235415
A10: CZK | B10: =COUNTIFS(c_currency,A10) -> 73 | C10: =B10/COUNTA(c_currency) -> 0.0365 | D10: =AVERAGEIFS(Clean!$E$2:$E$2001,c_currency,A10) -> 73.130137 | E10: =AVERAGEIFS(c_usd,c_currency,A10) -> 3.2502283
A11: KZT | B11: =COUNTIFS(c_currency,A11) -> 35 | C11: =B11/COUNTA(c_currency) -> 0.0175 | D11: =AVERAGEIFS(Clean!$E$2:$E$2001,c_currency,A11) -> 1047.3143 | E11: =AVERAGEIFS(c_usd,c_currency,A11) -> 2.1819048
A12: PLN | B12: =COUNTIFS(c_currency,A12) -> 21 | C12: =B12/COUNTA(c_currency) -> 0.0105 | D12: =AVERAGEIFS(Clean!$E$2:$E$2001,c_currency,A12) -> 9.7961905 | E12: =AVERAGEIFS(c_usd,c_currency,A12) -> 2.5779449
A13: SGD | B13: =COUNTIFS(c_currency,A13) -> 16 | C13: =B13/COUNTA(c_currency) -> 0.008 | D13: =AVERAGEIFS(Clean!$E$2:$E$2001,c_currency,A13) -> 3.3245625 | E13: =AVERAGEIFS(c_usd,c_currency,A13) -> 2.4626389
A14: ILS | B14: =COUNTIFS(c_currency,A14) -> 5 | C14: =B14/COUNTA(c_currency) -> 0.0025 | D14: =AVERAGEIFS(Clean!$E$2:$E$2001,c_currency,A14) -> 6.34 | E14: =AVERAGEIFS(c_usd,c_currency,A14) -> 1.7135135
A15: RUB | B15: =COUNTIFS(c_currency,A15) -> 4 | C15: =B15/COUNTA(c_currency) -> 0.002 | D15: =AVERAGEIFS(Clean!$E$2:$E$2001,c_currency,A15) -> 53.75 | E15: =AVERAGEIFS(c_usd,c_currency,A15) -> 0.55989583
A16: INR | B16: =COUNTIFS(c_currency,A16) -> 3 | C16: =B16/COUNTA(c_currency) -> 0.0015 | D16: =AVERAGEIFS(Clean!$E$2:$E$2001,c_currency,A16) -> 129.33333 | E16: =AVERAGEIFS(c_usd,c_currency,A16) -> 1.5396825
... A24: HUF | B24: =COUNTIFS(c_currency,A24) -> 1 | C24: =B24/COUNTA(c_currency) -> 0.0005 | D24: =AVERAGEIFS(Clean!$E$2:$E$2001,c_currency,A24) -> 1299 | E24: =AVERAGEIFS(c_usd,c_currency,A24) -> 3.6591549
A26: 2. Top 12 stores by record count
A27: Store | B27: Records | C27: Share of records | D27: Avg price (USD) | E27: Records with unnamed product
A28: Dumbo Market | B28: =COUNTIFS(c_store,A28) -> 289 | C28: =B28/COUNTA(c_store) -> 0.1445 | D28: =AVERAGEIFS(c_usd,c_store,A28) -> 10.976194 | E28: =COUNTIFS(c_store,A28,c_name_flag,"Yes") -> 0
A29: E. Leclerc | B29: =COUNTIFS(c_store,A29) -> 214 | C29: =B29/COUNTA(c_store) -> 0.107 | D29: =AVERAGEIFS(c_usd,c_store,A29) -> 2.8615908 | E29: =COUNTIFS(c_store,A29,c_name_flag,"Yes") -> 0
A30: Carrefour Market | B30: =COUNTIFS(c_store,A30) -> 202 | C30: =B30/COUNTA(c_store) -> 0.101 | D30: =AVERAGEIFS(c_usd,c_store,A30) -> 3.8909815 | E30: =COUNTIFS(c_store,A30,c_name_flag,"Yes") -> 0
A31: Colruyt | B31: =COUNTIFS(c_store,A31) -> 151 | C31: =B31/COUNTA(c_store) -> 0.0755 | D31: =AVERAGEIFS(c_usd,c_store,A31) -> 3.3532249 | E31: =COUNTIFS(c_store,A31,c_name_flag,"Yes") -> 0
A32: Monoprix | B32: =COUNTIFS(c_store,A32) -> 128 | C32: =B32/COUNTA(c_store) -> 0.064 | D32: =AVERAGEIFS(c_usd,c_store,A32) -> 4.2206182 | E32: =COUNTIFS(c_store,A32,c_name_flag,"Yes") -> 54
A33: Willys Landskrona Infarten | B33: =COUNTIFS(c_store,A33) -> 111 | C33: =B33/COUNTA(c_store) -> 0.0555 | D33: =AVERAGEIFS(c_usd,c_store,A33) -> 2.417762 | E33: =COUNTIFS(c_store,A33,c_name_flag,"Yes") -> 111
A34: Intermarché | B34: =COUNTIFS(c_store,A34) -> 87 | C34: =B34/COUNTA(c_store) -> 0.0435 | D34: =AVERAGEIFS(c_usd,c_store,A34) -> 3.7814843 | E34: =COUNTIFS(c_store,A34,c_name_flag,"Yes") -> 1
A35: Extra Danmarksplass | B35: =COUNTIFS(c_store,A35) -> 70 | C35: =B35/COUNTA(c_store) -> 0.035 | D35: =AVERAGEIFS(c_usd,c_store,A35) -> 3.7524242 | E35: =COUNTIFS(c_store,A35,c_name_flag,"Yes") -> 2
A36: Whole Foods Market | B36: =COUNTIFS(c_store,A36) -> 67 | C36: =B36/COUNTA(c_store) -> 0.0335 | D36: =AVERAGEIFS(c_usd,c_store,A36) -> 14.520597 | E36: =COUNTIFS(c_store,A36,c_name_flag,"Yes") -> 0
A37: Tropic | B37: =COUNTIFS(c_store,A37) -> 64 | C37: =B37/COUNTA(c_store) -> 0.032 | D37: =AVERAGEIFS(c_usd,c_store,A37) -> 2.5438042 | E37: =COUNTIFS(c_store,A37,c_name_flag,"Yes") -> 64
A38: Albert | B38: =COUNTIFS(c_store,A38) -> 60 | C38: =B38/COUNTA(c_store) -> 0.03 | D38: =AVERAGEIFS(c_usd,c_store,A38) -> 3.3739259 | E38: =COUNTIFS(c_store,A38,c_name_flag,"Yes") -> 0
A39: Rema 1000 Danmarksplass | B39: =COUNTIFS(c_store,A39) -> 58 | C39: =B39/COUNTA(c_store) -> 0.029 | D39: =AVERAGEIFS(c_usd,c_store,A39) -> 3.520202 | E39: =COUNTIFS(c_store,A39,c_name_flag,"Yes") -> 2
A41: 3. Monthly trend (USD, all currencies)
A42: Month | B42: Records | C42: Avg price (USD) | D42: Avg price (USD), items under $10
A43: 46054 | B43: =COUNTIFS(c_month,A43) -> 15 | C43: =AVERAGEIFS(c_usd,c_month,A43) -> 5.2766667 | D43: =AVERAGEIFS(c_usd,c_month,A43,c_usd,"<10") -> 4.8685714
A44: 46082 | B44: =COUNTIFS(c_month,A44) -> 8 | C44: =AVERAGEIFS(c_usd,c_month,A44) -> 1.2781792 | D44: =AVERAGEIFS(c_usd,c_month,A44,c_usd,"<10") -> 1.2781792
A45: 46113 | B45: =COUNTIFS(c_month,A45) -> 6 | C45: =AVERAGEIFS(c_usd,c_month,A45) -> 3.3342967 | D45: =AVERAGEIFS(c_usd,c_month,A45,c_usd,"<10") -> 3.3342967
A46: 46143 | B46: =COUNTIFS(c_month,A46) -> 88 | C46: =AVERAGEIFS(c_usd,c_month,A46) -> 2.6313058 | D46: =AVERAGEIFS(c_usd,c_month,A46,c_usd,"<10") -> 2.475583
A47: 46174 | B47: =COUNTIFS(c_month,A47) -> 14 | C47: =AVERAGEIFS(c_usd,c_month,A47) -> 1.9426094 | D47: =AVERAGEIFS(c_usd,c_month,A47,c_usd,"<10") -> 1.9426094
A48: 46204 | B48: =COUNTIFS(c_month,A48) -> 1 | C48: =AVERAGEIFS(c_usd,c_month,A48) -> 5.7745665 | D48: =AVERAGEIFS(c_usd,c_month,A48,c_usd,"<10") -> 5.7745665
A49: 46266 | B49: =COUNTIFS(c_month,A49) -> 686 | C49: =AVERAGEIFS(c_usd,c_month,A49) -> 6.7786816 | D49: =AVERAGEIFS(c_usd,c_month,A49,c_usd,"<10") -> 4.0291816
A50: 46296 | B50: =COUNTIFS(c_month,A50) -> 1182 | C50: =AVERAGEIFS(c_usd,c_month,A50) -> 3.8977154 | D50: =AVERAGEIFS(c_usd,c_month,A50,c_usd,"<10") -> 3.0695877
